Workbook

Sheet Linearização
B2: Linearização da Calibração no Computador de Vazão
C7: Informações Gerais
C9: Cliente: | D9: PRIO | K9: Nº Certificado: | M9: LMV 49874-26
C10: Instalação: | D10: FPSO BRAVO | K10: Modelo: | M10: TZN350-3500
C11: TAG do Sistema: | D11: FT-7145B-01 | K11: Fabricante: | M11: FAURE HERMAN
C12: Aplicação: | D12: TRANSFERÊNCIA DE CUSTÓDIA | K12: TAG: | M12: =D11 -> FT-7145B-01
C13: Sistema: | D13: OFFLOADING TRAMO B | K13: Nº Série: | M13: 9013404
C14: Data da Calibração: | D14: 46137 | K14: Diâmetro: | M14: 14"
C15: Tipo do Medidor: | D15: TURBINA | K15: Faixa Calibrada: | M15: 440 m³/h a 2500 m³/h
C17: Valores do Certificado de Calibração
C19: K-Factor do medidor: | D19: 70.3 | F19: pulsos/m³
C21: Vazão da Calibração (m³/h) | E21: Frequência (Hz) | G21: Volume de Referência (L) | I21: Volume do Medidor (L) | K21: Meter Factor | M21: Erro (%) | O21: K-factor corrigido | Q21: Incerteza (%) | S21: Status | V21: C=7 | W21: MF
C22: 440 | E22: =IFERROR(($D$19*C22)/3600,"") -> 8.5922222 | G22: 145953.57 | I22: 145713.61 | K22: 1.00165 | M22: -0.16 | O22: =IFERROR(ROUND($D$19/K22,5),"") -> 70.1842 | Q22: 0.15 | S22: =IF(C22="","", IF(OR($D$12="FISCAL",$D$12="TRANSFERÊNCIA DE CUSTÓDIA"),IF(ABS(M22)>0.2,"REPROVADO","APROVADO"), IF(ABS(M22)>0.6,"REPROVADO","APROVADO"))) -> APROVADO | V22: =LEN(O22)-1 -> 6 | W22: =(G22/I22)-K22 -> -3.2080497e-06
C23: 530 | E23: =IFERROR(($D$19*C23)/3600,"") -> 10.349722 | G23: 145925.9 | I23: 145765.77 | K23: 1.0011 | M23: -0.11 | O23: =IFERROR(ROUND($D$19/K23,5),"") -> 70.22275 | Q23: 0.15 | S23: =IF(C23="","", IF(OR($D$12="FISCAL",$D$12="TRANSFERÊNCIA DE CUSTÓDIA"),IF(ABS(M23)>0.2,"REPROVADO","APROVADO"), IF(ABS(M23)>0.6,"REPROVADO","APROVADO"))) -> APROVADO | V23: =LEN(O23)-1 -> 7 | W23: =(G23/I23)-K23 -> -1.4567686e-06
C24: 640 | E24: =IFERROR(($D$19*C24)/3600,"") -> 12.497778 | G24: 291858.88 | I24: 291631.1 | K24: 1.00078 | M24: -0.08 | O24: =IFERROR(ROUND($D$19/K24,5),"") -> 70.24521 | Q24: 0.15 | S24: =IF(C24="","", IF(OR($D$12="FISCAL",$D$12="TRANSFERÊNCIA DE CUSTÓDIA"),IF(ABS(M24)>0.2,"REPROVADO","APROVADO"), IF(ABS(M24)>0.6,"REPROVADO","APROVADO"))) -> APROVADO | V24: =LEN(O24)-1 -> 7 | W24: =(G24/I24)-K24 -> 1.0552441e-06
C25: 780 | E25: =IFERROR(($D$19*C25)/3600,"") -> 15.231667 | G25: 291805.28 | I25: 291863.44 | K25: 0.9998 | M25: 0.02 | O25: =IFERROR(ROUND($D$19/K25,5),"") -> 70.31406 | Q25: 0.15 | S25: =IF(C25="","", IF(OR($D$12="FISCAL",$D$12="TRANSFERÊNCIA DE CUSTÓDIA"),IF(ABS(M25)>0.2,"REPROVADO","APROVADO"), IF(ABS(M25)>0.6,"REPROVADO","APROVADO"))) -> APROVADO | V25: =LEN(O25)-1 -> 7 | W25: =(G25/I25)-K25 -> 7.2872437e-07
C26: 950 | E26: =IFERROR(($D$19*C26)/3600,"") -> 18.551389 | G26: 291750.56 | I26: 291872.93 | K26: 0.99958 | M26: 0.04 | O26: =IFERROR(ROUND($D$19/K26,5),"") -> 70.32954 | Q26: 0.15 | S26: =IF(C26="","", IF(OR($D$12="FISCAL",$D$12="TRANSFERÊNCIA DE CUSTÓDIA"),IF(ABS(M26)>0.2,"REPROVADO","APROVADO"), IF(ABS(M26)>0.6,"REPROVADO","APROVADO"))) -> APROVADO | V26: =LEN(O26)-1 -> 7 | W26: =(G26/I26)-K26 -> 7.422086e-07
C27: 1160 | E27: =IFERROR(($D$19*C27)/3600,"") -> 22.652222 | G27: 291644.07 | I27: 291778.09 | K27: 0.99954 | M27: 0.05 | O27: =IFERROR(ROUND($D$19/K27,5),"") -> 70.33235 | Q27: 0.15 | S27: =IF(C27="","", IF(OR($D$12="FISCAL",$D$12="TRANSFERÊNCIA DE CUSTÓDIA"),IF(ABS(M27)>0.2,"REPROVADO","APROVADO"), IF(ABS(M27)>0.6,"REPROVADO","APROVADO"))) -> APROVADO | V27: =LEN(O27)-1 -> 7 | W27: =(G27/I27)-K27 -> 6.7832852e-07
C28: 1400 | E28: =IFERROR(($D$19*C28)/3600,"") -> 27.338889 | G28: 444736.19 | I28: 445234.71 | K28: 0.99888 | M28: 0.11 | O28: =IFERROR(ROUND($D$19/K28,5),"") -> 70.37882 | Q28: 0.15 | S28: =IF(C28="","", IF(OR($D$12="FISCAL",$D$12="TRANSFERÊNCIA DE CUSTÓDIA"),IF(ABS(M28)>0.2,"REPROVADO","APROVADO"), IF(ABS(M28)>0.6,"REPROVADO","APROVADO"))) -> APROVADO | V28: =LEN(O28)-1 -> 7 | W28: =(G28/I28)-K28 -> 3.2089861e-07
C29: 1700 | E29: =IFERROR(($D$19*C29)/3600,"") -> 33.197222 | G29: 443800.32 | I29: 444324.32 | K29: 0.99882 | M29: 0.12 | O29: =IFERROR(ROUND($D$19/K29,5),"") -> 70.38305 | Q29: 0.15 | S29: =IF(C29="","", IF(OR($D$12="FISCAL",$D$12="TRANSFERÊNCIA DE CUSTÓDIA"),IF(ABS(M29)>0.2,"REPROVADO","APROVADO"), IF(ABS(M29)>0.6,"REPROVADO","APROVADO"))) -> APROVADO | V29: =LEN(O29)-1 -> 7 | W29: =(G29/I29)-K29 -> 6.8125373e-07
C30: 2060 | E30: =IFERROR(($D$19*C30)/3600,"") -> 40.227222 | G30: 443872.38 | I30: 444495.02 | K30: 0.9986 | M30: 0.14 | O30: =IFERROR(ROUND($D$19/K30,5),"") -> 70.39856 | Q30: 0.15 | S30: =IF(C30="","", IF(OR($D$12="FISCAL",$D$12="TRANSFERÊNCIA DE CUSTÓDIA"),IF(ABS(M30)>0.2,"REPROVADO","APROVADO"), IF(ABS(M30)>0.6,"REPROVADO","APROVADO"))) -> APROVADO | V30: =LEN(O30)-1 -> 7 | W30: =(G30/I30)-K30 -> -7.8059817e-07
C31: 2500 | E31: =IFERROR(($D$19*C31)/3600,"") -> 48.819444 | G31: 442423.01 | I31: 443176.86 | K31: 0.9983 | M31: 0.17 | O31: =IFERROR(ROUND($D$19/K31,5),"") -> 70.41971 | Q31: 0.15 | S31: =IF(C31="","", IF(OR($D$12="FISCAL",$D$12="TRANSFERÊNCIA DE CUSTÓDIA"),IF(ABS(M31)>0.2,"REPROVADO","APROVADO"), IF(ABS(M31)>0.6,"REPROVADO","APROVADO"))) -> APROVADO | V31: =LEN(O31)-1 -> 7 | W31: =(G31/I31)-K31 -> -1.0139022e-06
E32: =IFERROR(($D$19*C32)/3600,"") -> 0 | K32: =IFERROR(G32/I32,"") | O32: =IFERROR(ROUND($D$19/K32,5),"") | S32: =IF(C32="","", IF(OR($D$12="FISCAL",$D$12="TRANSFERÊNCIA DE CUSTÓDIA"),IF(ABS(M32)>0.2,"REPROVADO","APROVADO"), IF(ABS(M32)>0.6,"REPROVADO","APROVADO"))) | V32: =LEN(O32)-1 -> -1
E33: =IFERROR(($D$19*C33)/3600,"") -> 0 | K33: =IFERROR(G33/I33,"") | O33: =IFERROR(ROUND($D$19/K33,5),"") | S33: =IF(C33="","", IF(OR($D$12="FISCAL",$D$12="TRANSFERÊNCIA DE CUSTÓDIA"),IF(ABS(M33)>0.2,"REPROVADO","APROVADO"), IF(ABS(M33)>0.6,"REPROVADO","APROVADO"))) | V33: =LEN(O33)-1 -> -1
E34: =IFERROR(($D$19*C34)/3600,"") -> 0 | K34: =IFERROR(G34/I34,"") | O34: =IFERROR(ROUND($D$19/K34,5),"") | S34: =IF(C34="","", IF(OR($D$12="FISCAL",$D$12="TRANSFERÊNCIA DE CUSTÓDIA"),IF(ABS(M34)>0.2,"REPROVADO","APROVADO"), IF(ABS(M34)>0.6,"REPROVADO","APROVADO"))) | V34: =LEN(O34)-1 -> -1
E35: =IFERROR(($D$19*C35)/3600,"") -> 0 | K35: =IFERROR(G35/I35,"") | O35: =IFERROR(ROUND($D$19/K35,5),"") | S35: =IF(C35="","", IF(OR($D$12="FISCAL",$D$12="TRANSFERÊNCIA DE CUSTÓDIA"),IF(ABS(M35)>0.2,"REPROVADO","APROVADO"), IF(ABS(M35)>0.6,"REPROVADO","APROVADO"))) | V35: =LEN(O35)-1 -> -1
E36: =IFERROR(($D$19*C36)/3600,"") -> 0 | K36: =IFERROR(G36/I36,"") | O36: =IFERROR(ROUND($D$19/K36,5),"") | S36: =IF(C36="","", IF(OR($D$12="FISCAL",$D$12="TRANSFERÊNCIA DE CUSTÓDIA"),IF(ABS(M36)>0.2,"REPROVADO","APROVADO"), IF(ABS(M36)>0.6,"REPROVADO","APROVADO"))) | V36: =LEN(O36)-1 -> -1
E37: =IFERROR(($D$19*C37)/3600,"") -> 0 | K37: =IFERROR(G37/I37,"") | O37: =IFERROR(ROUND($D$19/K37,5),"") | S37: =IF(C37="","", IF(OR($D$12="FISCAL",$D$12="TRANSFERÊNCIA DE CUSTÓDIA"),IF(ABS(M37)>0.2,"REPROVADO","APROVADO"), IF(ABS(M37)>0.6,"REPROVADO","APROVADO"))) | V37: =LEN(O37)-1 -> -1
E38: =IFERROR(($D$19*C38)/3600,"") -> 0 | K38: =IFERROR(G38/I38,"") | O38: =IFERROR(ROUND($D$19/K38,5),"") | S38: =IF(C38="","", IF(OR($D$12="FISCAL",$D$12="TRANSFERÊNCIA DE CUSTÓDIA"),IF(ABS(M38)>0.2,"REPROVADO","APROVADO"), IF(ABS(M38)>0.6,"REPROVADO","APROVADO"))) | V38: =LEN(O38)-1 -> -1
E39: =IFERROR(($D$19*C39)/3600,"") -> 0 | K39: =IFERROR(G39/I39,"") | O39: =IFERROR(ROUND($D$19/K39,5),"") | S39: =IF(C39="","", IF(OR($D$12="FISCAL",$D$12="TRANSFERÊNCIA DE CUSTÓDIA"),IF(ABS(M39)>0.2,"REPROVADO","APROVADO"), IF(ABS(M39)>0.6,"REPROVADO","APROVADO"))) | V39: =LEN(O39)-1 -> -1
E40: =IFERROR(($D$19*C40)/3600,"") -> 0 | K40: =IFERROR(G40/I40,"") | O40: =IFERROR(ROUND($D$19/K40,5),"") | S40: =IF(C40="","", IF(OR($D$12="FISCAL",$D$12="TRANSFERÊNCIA DE CUSTÓDIA"),IF(ABS(M40)>0.2,"REPROVADO","APROVADO"), IF(ABS(M40)>0.6,"REPROVADO","APROVADO"))) | V40: =LEN(O40)-1 -> -1
E41: =IFERROR(($D$19*C41)/3600,"") -> 0 | K41: =IFERROR(G41/I41,"") | O41: =IFERROR(ROUND($D$19/K41,5),"") | S41: =IF(C41="","", IF(OR($D$12="FISCAL",$D$12="TRANSFERÊNCIA DE CUSTÓDIA"),IF(ABS(M41)>0.2,"REPROVADO","APROVADO"), IF(ABS(M41)>0.6,"REPROVADO","APROVADO"))) | V41: =LEN(O41)-1 -> -1
C43: Fórmulas
C45: F (Hz) = (K-Factor do medidor*Vazão) / 3600 | I45: MF = Volume de Referência / Volume do Medidor | M45: KFc = K-Factor do medidor / MF
C47: F = Frequência em Hz | I47: MF = Meter Factor | M47: KFc = K-Factor Corrigido
C48: K-Factor do medidor | I48: Volume de Referência em m³ | M48: K- Factor do medidor
C49: Vazão em m³/h | I49: Volume do Medidor em m³ | M49: MF da vazão
C50: 3600 referente à conversão de horas para segundos
C52: Dados à Serem Configurados no Computador de Vazão
H55: N° | I55: Vazão da Calibração (m³/h) | K55: Frequência (Hz) | L55: K-factor corrigido
...

Sheet Falha Presumida
B2: Avaliação de Falha Presumida de Medição
C7: Informações Gerais
C9: Cliente: | D9: =Linearização!D9 -> PRIO | K9: Nº Certificado: | M9: =Linearização!M9 -> LMV 49874-26
C10: Instalação: | D10: =Linearização!D10 -> FPSO BRAVO | K10: Modelo: | M10: =Linearização!M10 -> TZN350-3500
C11: TAG do Sistema: | D11: =Linearização!D11 -> FT-7145B-01 | K11: Fabricante: | M11: =Linearização!M11 -> FAURE HERMAN
C12: Aplicação: | D12: =Linearização!D12 -> TRANSFERÊNCIA DE CUSTÓDIA | K12: TAG: | M12: =Linearização!M12 -> FT-7145B-01
C13: Sistema: | D13: =Linearização!D13 -> OFFLOADING TRAMO B | K13: Nº Série: | M13: =Linearização!M13 -> 9013404
C14: Data da Calibração: | D14: =Linearização!D14 -> 46137 | K14: Diâmetro: | M14: =Linearização!M14 -> 14"
C15: Tipo do Medidor: | D15: =Linearização!D15 -> TURBINA | K15: Faixa Calibrada: | M15: =Linearização!M15 -> 440 m³/h a 2500 m³/h
C17: Valores do Certificado de Calibração
C19: K-Factor do medidor: | D19: =Linearização!D19 -> 70.3 | F19: pulsos/m³
C21: =Linearização!C21 -> Vazão da Calibração (m³/h) | E21: =Linearização!E21 -> Frequência (Hz) | G21: =Linearização!G21 -> Volume de Referência (L) | I21: =Linearização!I21 -> Volume do Medidor (L) | K21: =Linearização!K21 -> Meter Factor | M21: =Linearização!M21 -> Erro (%) | O21: =Linearização!O21 -> K-factor corrigido | Q21: =Linearização!Q21 -> Incerteza (%) | S21: =Linearização!S21 -> Status
C22: =Linearização!C22 -> 440 | E22: =Linearização!E22 -> 8.5922222 | G22: =Linearização!G22 -> 145953.57 | I22: =Linearização!I22 -> 145713.61 | K22: =Linearização!K22 -> 1.00165 | M22: =Linearização!M22 -> -0.16 | O22: =Linearização!O22 -> 70.1842 | Q22: =Linearização!Q22 -> 0.15 | S22: =Linearização!S22 -> APROVADO
C23: =Linearização!C23 -> 530 | E23: =Linearização!E23 -> 10.349722 | G23: =Linearização!G23 -> 145925.9 | I23: =Linearização!I23 -> 145765.77 | K23: =Linearização!K23 -> 1.0011 | M23: =Linearização!M23 -> -0.11 | O23: =Linearização!O23 -> 70.22275 | Q23: =Linearização!Q23 -> 0.15 | S23: =Linearização!S23 -> APROVADO
C24: =Linearização!C24 -> 640 | E24: =Linearização!E24 -> 12.497778 | G24: =Linearização!G24 -> 291858.88 | I24: =Linearização!I24 -> 291631.1 | K24: =Linearização!K24 -> 1.00078 | M24: =Linearização!M24 -> -0.08 | O24: =Linearização!O24 -> 70.24521 | Q24: =Linearização!Q24 -> 0.15 | S24: =Linearização!S24 -> APROVADO
C25: =Linearização!C25 -> 780 | E25: =Linearização!E25 -> 15.231667 | G25: =Linearização!G25 -> 291805.28 | I25: =Linearização!I25 -> 291863.44 | K25: =Linearização!K25 -> 0.9998 | M25: =Linearização!M25 -> 0.02 | O25: =Linearização!O25 -> 70.31406 | Q25: =Linearização!Q25 -> 0.15 | S25: =Linearização!S25 -> APROVADO
C26: =Linearização!C26 -> 950 | E26: =Linearização!E26 -> 18.551389 | G26: =Linearização!G26 -> 291750.56 | I26: =Linearização!I26 -> 291872.93 | K26: =Linearização!K26 -> 0.99958 | M26: =Linearização!M26 -> 0.04 | O26: =Linearização!O26 -> 70.32954 | Q26: =Linearização!Q26 -> 0.15 | S26: =Linearização!S26 -> APROVADO
C27: =Linearização!C27 -> 1160 | E27: =Linearização!E27 -> 22.652222 | G27: =Linearização!G27 -> 291644.07 | I27: =Linearização!I27 -> 291778.09 | K27: =Linearização!K27 -> 0.99954 | M27: =Linearização!M27 -> 0.05 | O27: =Linearização!O27 -> 70.33235 | Q27: =Linearização!Q27 -> 0.15 | S27: =Linearização!S27 -> APROVADO
C28: =Linearização!C28 -> 1400 | E28: =Linearização!E28 -> 27.338889 | G28: =Linearização!G28 -> 444736.19 | I28: =Linearização!I28 -> 445234.71 | K28: =Linearização!K28 -> 0.99888 | M28: =Linearização!M28 -> 0.11 | O28: =Linearização!O28 -> 70.37882 | Q28: =Linearização!Q28 -> 0.15 | S28: =Linearização!S28 -> APROVADO
C29: =Linearização!C29 -> 1700 | E29: =Linearização!E29 -> 33.197222 | G29: =Linearização!G29 -> 443800.32 | I29: =Linearização!I29 -> 444324.32 | K29: =Linearização!K29 -> 0.99882 | M29: =Linearização!M29 -> 0.12 | O29: =Linearização!O29 -> 70.38305 | Q29: =Linearização!Q29 -> 0.15 | S29: =Linearização!S29 -> APROVADO
C30: =Linearização!C30 -> 2060 | E30: =Linearização!E30 -> 40.227222 | G30: =Linearização!G30 -> 443872.38 | I30: =Linearização!I30 -> 444495.02 | K30: =Linearização!K30 -> 0.9986 | M30: =Linearização!M30 -> 0.14 | O30: =Linearização!O30 -> 70.39856 | Q30: =Linearização!Q30 -> 0.15 | S30: =Linearização!S30 -> APROVADO
C31: =Linearização!C31 -> 2500 | E31: =Linearização!E31 -> 48.819444 | G31: =Linearização!G31 -> 442423.01 | I31: =Linearização!I31 -> 443176.86 | K31: =Linearização!K31 -> 0.9983 | M31: =Linearização!M31 -> 0.17 | O31: =Linearização!O31 -> 70.41971 | Q31: =Linearização!Q31 -> 0.15 | S31: =Linearização!S31 -> APROVADO
C32: =Linearização!C32 -> 0 | E32: =Linearização!E32 -> 0 | G32: =Linearização!G32 -> 0 | I32: =Linearização!I32 -> 0 | K32: =Linearização!K32 | M32: =Linearização!M32 -> 0 | O32: =Linearização!O32 | Q32: =Linearização!Q32 -> 0 | S32: =Linearização!S32
... C41: =Linearização!C41 -> 0 | E41: =Linearização!E41 -> 0 | G41: =Linearização!G41 -> 0 | I41: =Linearização!I41 -> 0 | K41: =Linearização!K41 | M41: =Linearização!M41 -> 0 | O41: =Linearização!O41 | Q41: =Linearização!Q41 -> 0 | S41: =Linearização!S41
C43: Fórmulas
C45: F (Hz) = (K-Factor do medidor*Vazão) / 3600 | I45: MF = Volume de Referência / Volume do Medidor | M45: KFc = K-Factor do medidor / MF
C47: F = Frequência em Hz | I47: MF = Meter Factor | M47: KFc = K-Factor Corrigido
C48: K-Factor do medidor | I48: Volume de Referência em m³ | M48: K- Factor do medidor
C49: Vazão em m³/h | I49: Volume do Medidor em m³ | M49: MF da vazão
C50: 3600 referente à conversão de horas para segundos
C52: Dados à Serem Configurados no Computador de Vazão
H55: N° | I55: Vazão da Calibração (m³/h) | K55: Frequência (Hz) | L55: K-factor corrigido
H56: 1 | I56: =C22 -> 440 | K56: =E22 -> 8.5922222 | L56: =O22 -> 70.1842 | XFC56: Meter Factor
H57: 2 | I57: =C23 -> 530 | K57: =E23 -> 10.349722 | L57: =O23 -> 70.22275 | XFC57: =K22 -> 1.00165
H58: 3 | I58: =C24 -> 640 | K58: =E24 -> 12.497778 | L58: =O24 -> 70.24521 | XFC58: =K23 -> 1.0011
H59: 4 | I59: =C25 -> 780 | K59: =E25 -> 15.231667 | L59: =O25 -> 70.31406 | XFC59: =K24 -> 1.00078
H60: 5 | I60: =C26 -> 950 | K60: =E26 -> 18.551389 | L60: =O26 -> 70.32954 | XFC60: =K25 -> 0.9998
H61: 6 | I61: =#REF! -> #REF! | K61: =#REF! -> #REF! | L61: =#REF! -> #REF! | XFC61: =K26 -> 0.99958
H62: 7 | I62: =#REF! -> #REF! | K62: =#REF! -> #REF! | L62: =#REF! -> #REF! | XFC62: =#REF! -> #REF!
K75: KF médio | L75: =AVERAGE(L56:M62) -> #REF!
...
